<?xml version="1.0" ?>
<!-- =================================================================================== -->
<!-- |    This document was autogenerated by xacro from rocker.urdf.xacro              | -->
<!-- |    EDITING THIS FILE BY HAND IS NOT RECOMMENDED                                 | -->
<!-- =================================================================================== -->
<!-- This URDF was automatically created by SolidWorks to URDF Exporter! Originally created by Stephen Brawner (brawner@gmail.com) 
     Commit Version: 1.6.0-4-g7f85cfe  Build Version: 1.6.7995.38578
     For more information, please see http://wiki.ros.org/sw_urdf_exporter -->
<robot name="rocker">
  <!-- Wheels friction tuning -->
  <gazebo reference="fl_wheel">
    <mu1>1.0</mu1>
    <mu2>1.0</mu2>
    <kp>1e6</kp>
    <kd>10.0</kd>
    <minDepth>0.001</minDepth>
    <maxVel>0.5</maxVel>
    <fdir1>1 0 0</fdir1>
  </gazebo>
  <gazebo reference="fr_wheel">
    <mu1>1.0</mu1>
    <mu2>1.0</mu2>
    <kp>1e6</kp>
    <kd>10.0</kd>
    <minDepth>0.001</minDepth>
    <maxVel>0.5</maxVel>
    <fdir1>1 0 0</fdir1>
  </gazebo>
  <gazebo reference="rl_wheel">
    <mu1>1.0</mu1>
    <mu2>1.0</mu2>
    <kp>1e6</kp>
    <kd>10.0</kd>
    <minDepth>0.001</minDepth>
    <maxVel>0.5</maxVel>
    <fdir1>1 0 0</fdir1>
  </gazebo>
  <gazebo reference="rr_wheel">
    <mu1>1.0</mu1>
    <mu2>1.0</mu2>
    <kp>1e6</kp>
    <kd>10.0</kd>
    <minDepth>0.001</minDepth>
    <maxVel>0.5</maxVel>
    <fdir1>1 0 0</fdir1>
  </gazebo>
  <!-- Steering friction -->
  <gazebo reference="steer_fl">
    <mu1>1.0</mu1>
    <mu2>1.0</mu2>
    <kp>100000.0</kp>
    <kd>10.0</kd>
  </gazebo>
  <gazebo reference="steer_fr">
    <mu1>1.0</mu1>
    <mu2>1.0</mu2>
    <kp>100000.0</kp>
    <kd>10.0</kd>
  </gazebo>
  <gazebo reference="steer_rl">
    <mu1>1.0</mu1>
    <mu2>1.0</mu2>
    <kp>100000.0</kp>
    <kd>10.0</kd>
  </gazebo>
  <gazebo reference="steer_rr">
    <mu1>1.0</mu1>
    <mu2>1.0</mu2>
    <kp>100000.0</kp>
    <kd>10.0</kd>
  </gazebo>
  <!-- Global plugins (for Ignition) -->
  <gazebo>
    <plugin filename="ign_ros2_control-system" name="ign_ros2_control::IgnitionROS2ControlPlugin">
      <parameters>/home/ajay/rocker_ws/install/rocker_controller/share/rocker_controller/config/rocker_controllers.yaml</parameters>
    </plugin>
    <plugin filename="ignition-gazebo-imu-system" name="ignition::gazebo::systems::Imu"/>
    <plugin filename="ignition-gazebo-sensors-system" name="ignition::gazebo::systems::Sensors"/>
  </gazebo>
  <link name="base_link">
    <inertial>
      <origin rpy="0 0 0" xyz="0.0036425 -1.0237E-05 0.029007"/>
      <mass value="3.2505"/>
      <inertia ixx="0.012194" ixy="-1.2887E-11" ixz="-1.2673E-05" iyy="0.0094514" iyz="2.0372E-12" izz="0.019133"/>
    </inertial>
    <visual>
      <origin rpy="0 0 0" xyz="0 0 0"/>
      <geometry>
        <mesh filename="package://rocker_description/meshes/base_link.STL"/>
      </geometry>
      <material name="">
        <color rgba="1 0 0 1"/>
      </material>
    </visual>
    <collision>
      <origin rpy="0 0 0" xyz="0 0 0"/>
      <geometry>
        <mesh filename="package://rocker_description/meshes/base_link.STL"/>
      </geometry>
    </collision>
  </link>
  <link name="rocker_left">
    <inertial>
      <origin rpy="0 0 0" xyz="-0.00596279660858899 0.019311656764223 0.00821775119149987"/>
      <mass value="0.548279465838668"/>
      <inertia ixx="0.000160712183052689" ixy="-1.18295174930768E-05" ixz="4.65341223670499E-08" iyy="0.00145712336712729" iyz="2.38546500296045E-06" izz="0.00150112676272773"/>
    </inertial>
    <visual>
      <origin rpy="0 0 0" xyz="0 0 0"/>
      <geometry>
        <mesh filename="package://rocker_description/meshes/rocker_left.STL"/>
      </geometry>
      <material name="">
        <color rgba="0.752941176470588 0.752941176470588 0.752941176470588 1"/>
      </material>
    </visual>
    <collision>
      <origin rpy="0 0 0" xyz="0 0 0"/>
      <geometry>
        <mesh filename="package://rocker_description/meshes/rocker_left.STL"/>
      </geometry>
    </collision>
  </link>
  <joint name="rocker_left_joint" type="revolute">
    <origin rpy="-1.5707963267949 0 0" xyz="-0.00300007366280326 0.139989762643875 0.00599815142431871"/>
    <parent link="base_link"/>
    <child link="rocker_left"/>
    <axis xyz="0 0 -1"/>
    <limit effort="10" lower="-0.785" upper="0.785" velocity="20"/>
  </joint>
  <link name="steer_fl">
    <inertial>
      <origin rpy="0 0 0" xyz="0.000519302762488599 0.00116147480983056 -0.0722490116852784"/>
      <mass value="0.0538768863875911"/>
      <inertia ixx="1.72835692168003E-05" ixy="1.86520451951073E-10" ixz="1.22945601642171E-09" iyy="1.26504996734862E-05" iyz="1.03486603556425E-12" izz="1.01151748087639E-05"/>
    </inertial>
    <visual>
      <origin rpy="0 0 0" xyz="0 0 0"/>
      <geometry>
        <mesh filename="package://rocker_description/meshes/steer_fl.STL"/>
      </geometry>
      <material name="">
        <color rgba="0.752941176470588 0.752941176470588 0.752941176470588 1"/>
      </material>
    </visual>
    <collision>
      <origin rpy="0 0 0" xyz="0 0 0"/>
      <geometry>
        <mesh filename="package://rocker_description/meshes/steer_fl.STL"/>
      </geometry>
    </collision>
  </link>
  <joint name="steer_fl_joint" type="revolute">
    <origin rpy="1.5707963267949 0 0" xyz="0.109493624388031 0.03794110103799 0.0465656792826112"/>
    <parent link="rocker_left"/>
    <child link="steer_fl"/>
    <axis xyz="0 0 -1"/>
    <limit effort="10" lower="-3.14" upper="3.14" velocity="20"/>
  </joint>
  <link name="fl_wheel">
    <inertial>
      <origin rpy="0 0 0" xyz="0.002099 -0.0019395 -0.028409"/>
      <mass value="0.13017"/>
      <inertia ixx="0.00012478" ixy="-7.5675E-12" ixz="-1.0928E-11" iyy="0.00012478" iyz="-2.364E-12" izz="0.00023467"/>
    </inertial>
    <visual>
      <origin rpy="0 0 0" xyz="0 0 0"/>
      <geometry>
        <mesh filename="package://rocker_description/meshes/fl_wheel.STL"/>
      </geometry>
      <material name="">
        <color rgba="0 0 0 1"/>
      </material>
    </visual>
    <collision>
      <origin rpy="0 0 0" xyz="0 0 0"/>
      <geometry>
        <mesh filename="package://rocker_description/meshes/fl_wheel.STL"/>
      </geometry>
    </collision>
  </link>
  <joint name="fl_wheel_joint" type="continuous">
    <origin rpy="-1.5707963267949 0 0" xyz="-0.0015781170593388 0.0908967088232542 -0.0809547532967621"/>
    <parent link="steer_fl"/>
    <child link="fl_wheel"/>
    <axis xyz="0 0 -1"/>
    <limit effort="10" lower="-10" upper="10" velocity="100"/>
  </joint>
  <link name="steer_rl">
    <inertial>
      <origin rpy="0 0 0" xyz="0.000484941628677482 0.00116147483099063 -0.0761644404434853"/>
      <mass value="0.053876886763219"/>
      <inertia ixx="1.72835692136404E-05" ixy="1.8652062791263E-10" ixz="1.22944997559593E-09" iyy="1.26504996782381E-05" iyz="1.04212079064367E-12" izz="1.01151748208476E-05"/>
    </inertial>
    <visual>
      <origin rpy="0 0 0" xyz="0 0 0"/>
      <geometry>
        <mesh filename="package://rocker_description/meshes/steer_rl.STL"/>
      </geometry>
      <material name="">
        <color rgba="0.752941176470588 0.752941176470588 0.752941176470588 1"/>
      </material>
    </visual>
    <collision>
      <origin rpy="0 0 0" xyz="0 0 0"/>
      <geometry>
        <mesh filename="package://rocker_description/meshes/steer_rl.STL"/>
      </geometry>
    </collision>
  </link>
  <joint name="steer_rl_joint" type="revolute">
    <origin rpy="1.5707963267949 0 0" xyz="-0.110472012747799 0.0340528521482858 0.0465656792826093"/>
    <parent link="rocker_left"/>
    <child link="steer_rl"/>
    <axis xyz="0 0 -1"/>
    <limit effort="10" lower="-3.14" upper="3.14" velocity="20"/>
  </joint>
  <link name="rl_wheel">
    <inertial>
      <origin rpy="0 0 0" xyz="0.0020646 0.001976 -0.028409"/>
      <mass value="0.13017"/>
      <inertia ixx="0.00012478" ixy="3.8397E-11" ixz="1.7184E-12" iyy="0.00012478" iyz="1.1048E-11" izz="0.00023467"/>
    </inertial>
    <visual>
      <origin rpy="0 0 0" xyz="0 0 0"/>
      <geometry>
        <mesh filename="package://rocker_description/meshes/rl_wheel.STL"/>
      </geometry>
      <material name="">
        <color rgba="0 0 0 1"/>
      </material>
    </visual>
    <collision>
      <origin rpy="0 0 0" xyz="0 0 0"/>
      <geometry>
        <mesh filename="package://rocker_description/meshes/rl_wheel.STL"/>
      </geometry>
    </collision>
  </link>
  <joint name="rl_wheel_joint" type="continuous">
    <origin rpy="-1.5707963267949 0 0" xyz="-0.00157811705934295 0.0908967088232554 -0.0809547532967675"/>
    <parent link="steer_rl"/>
    <child link="rl_wheel"/>
    <axis xyz="0 0 -1"/>
    <limit effort="10" lower="-10" upper="10" velocity="100"/>
  </joint>
  <link name="rocker_right">
    <inertial>
      <origin rpy="0 0 0" xyz="-0.00596288564139164 -0.0193116567738485 0.00817977279760604"/>
      <mass value="0.54827946587469"/>
      <inertia ixx="0.000160712214952262" ixy="1.17004377021412E-05" ixz="-4.595305488417E-08" iyy="0.00145712333524181" iyz="-2.31782014461646E-06" izz="0.00150112676273801"/>
    </inertial>
    <visual>
      <origin rpy="0 0 0" xyz="0 0 0"/>
      <geometry>
        <mesh filename="package://rocker_description/meshes/rocker_right.STL"/>
      </geometry>
      <material name="">
        <color rgba="0.752941176470588 0.752941176470588 0.752941176470588 1"/>
      </material>
    </visual>
    <collision>
      <origin rpy="0 0 0" xyz="0 0 0"/>
      <geometry>
        <mesh filename="package://rocker_description/meshes/rocker_right.STL"/>
      </geometry>
    </collision>
  </link>
  <joint name="rocker_right_joint" type="revolute">
    <origin rpy="1.5707963267949 0 0" xyz="-0.00300007366280228 -0.140010237356125 0.00599815142431871"/>
    <parent link="base_link"/>
    <child link="rocker_right"/>
    <axis xyz="0 0 -1"/>
    <limit effort="10" lower="-0.785" upper="0.785" velocity="20"/>
  </joint>
  <link name="steer_fr">
    <inertial>
      <origin rpy="0 0 0" xyz="0.000814806507593191 -0.00116147489072244 -0.0722542107353949"/>
      <mass value="0.0538768872737433"/>
      <inertia ixx="1.7283569426659E-05" ixy="1.86515428145444E-10" ixz="5.41775108617785E-10" iyy="1.26504997390041E-05" iyz="-9.97068339061866E-13" izz="1.01151746673558E-05"/>
    </inertial>
    <visual>
      <origin rpy="0 0 0" xyz="0 0 0"/>
      <geometry>
        <mesh filename="package://rocker_description/meshes/steer_fr.STL"/>
      </geometry>
      <material name="">
        <color rgba="0.752941176470588 0.752941176470588 0.752941176470588 1"/>
      </material>
    </visual>
    <collision>
      <origin rpy="0 0 0" xyz="0 0 0"/>
      <geometry>
        <mesh filename="package://rocker_description/meshes/steer_fr.STL"/>
      </geometry>
    </collision>
  </link>
  <joint name="steer_fr_joint" type="revolute">
    <origin rpy="-1.5707963267949 0 0" xyz="0.109199494929351 -0.0379359018234412 0.0464809030708809"/>
    <parent link="rocker_right"/>
    <child link="steer_fr"/>
    <axis xyz="0 0 -1"/>
    <limit effort="10" lower="-3.14" upper="3.14" velocity="20"/>
  </joint>
  <link name="fr_wheel">
    <inertial>
      <origin rpy="0 0 0" xyz="0.002099 -0.0019395 0.028409"/>
      <mass value="0.13017"/>
      <inertia ixx="0.00012478" ixy="-4.1966E-11" ixz="2.4004E-12" iyy="0.00012478" iyz="-1.092E-11" izz="0.00023467"/>
    </inertial>
    <visual>
      <origin rpy="0 0 0" xyz="0 0 0"/>
      <geometry>
        <mesh filename="package://rocker_description/meshes/fr_wheel.STL"/>
      </geometry>
      <material name="">
        <color rgba="0 0 0 1"/>
      </material>
    </visual>
    <collision>
      <origin rpy="0 0 0" xyz="0 0 0"/>
      <geometry>
        <mesh filename="package://rocker_description/meshes/fr_wheel.STL"/>
      </geometry>
    </collision>
  </link>
  <joint name="fr_wheel_joint" type="continuous">
    <origin rpy="-1.5707963267949 0 0" xyz="-0.00128398760065623 -0.0908967088232549 -0.0809599525113137"/>
    <parent link="steer_fr"/>
    <child link="fr_wheel"/>
    <axis xyz="0 0 -1"/>
    <limit effort="10" lower="-10" upper="10" velocity="100"/>
  </joint>
  <link name="steer_rr">
    <inertial>
      <origin rpy="0 0 0" xyz="0.000780445270329057 -0.00116147487171195 -0.0761696395712882"/>
      <mass value="0.0538768871625175"/>
      <inertia ixx="1.72835694318758E-05" ixy="1.86519124149826E-10" ixz="5.41758961396237E-10" iyy="1.26504997202066E-05" iyz="-9.97542075043563E-13" izz="1.01151746450203E-05"/>
    </inertial>
    <visual>
      <origin rpy="0 0 0" xyz="0 0 0"/>
      <geometry>
        <mesh filename="package://rocker_description/meshes/steer_rr.STL"/>
      </geometry>
      <material name="">
        <color rgba="0.752941176470588 0.752941176470588 0.752941176470588 1"/>
      </material>
    </visual>
    <collision>
      <origin rpy="0 0 0" xyz="0 0 0"/>
      <geometry>
        <mesh filename="package://rocker_description/meshes/steer_rr.STL"/>
      </geometry>
    </collision>
  </link>
  <joint name="steer_rr_joint" type="revolute">
    <origin rpy="-1.5707963267949 0 0" xyz="-0.11076614220648 -0.0340476529337355 0.0464809030708823"/>
    <parent link="rocker_right"/>
    <child link="steer_rr"/>
    <axis xyz="0 0 -1"/>
    <limit effort="10" lower="-3.14" upper="3.14" velocity="20"/>
  </joint>
  <link name="rr_wheel">
    <inertial>
      <origin rpy="0 0 0" xyz="-1.3569E-08 -1.2666E-08 0.0084087"/>
      <mass value="0.13017"/>
      <inertia ixx="0.00012478" ixy="3.6109E-11" ixz="-1.1101E-11" iyy="0.00012478" iyz="-1.3289E-12" izz="0.00023467"/>
    </inertial>
    <visual>
      <origin rpy="0 0 0" xyz="0 0 0"/>
      <geometry>
        <mesh filename="package://rocker_description/meshes/rr_wheel.STL"/>
      </geometry>
      <material name="">
        <color rgba="0 0 0 1"/>
      </material>
    </visual>
    <collision>
      <origin rpy="0 0 0" xyz="0 0 0"/>
      <geometry>
        <mesh filename="package://rocker_description/meshes/rr_wheel.STL"/>
      </geometry>
    </collision>
  </link>
  <joint name="rr_wheel_joint" type="continuous">
    <origin rpy="-1.5707963267949 0 0" xyz="0.000780594104818705 -0.0708967088232536 -0.0829359361237778"/>
    <parent link="steer_rr"/>
    <child link="rr_wheel"/>
    <axis xyz="0 0 -1"/>
    <limit effort="10" lower="-10" upper="10" velocity="100"/>
  </joint>
  <link name="diff_link">
    <inertial>
      <origin rpy="0 0 0" xyz="0.0236047033494913 3.3860603747965E-07 0.00680399175128785"/>
      <mass value="0.218473302594945"/>
      <inertia ixx="0.000709218973632844" ixy="-4.54890286672036E-11" ixz="-5.80923681517665E-07" iyy="2.67923062738046E-05" iyz="-9.28200200488253E-10" izz="0.000717476916902687"/>
    </inertial>
    <visual>
      <origin rpy="0 0 0" xyz="0 0 0"/>
      <geometry>
        <mesh filename="package://rocker_description/meshes/diff_link.STL"/>
      </geometry>
      <material name="">
        <color rgba="0.752941176470588 0.752941176470588 0.752941176470588 1"/>
      </material>
    </visual>
    <collision>
      <origin rpy="0 0 0" xyz="0 0 0"/>
      <geometry>
        <mesh filename="package://rocker_description/meshes/diff_link.STL"/>
      </geometry>
    </collision>
  </link>
  <joint name="diff_link_joint" type="revolute">
    <origin rpy="0 0 0" xyz="0.0719999263371985 -1.02373561229607E-05 0.0659981514243161"/>
    <parent link="base_link"/>
    <child link="diff_link"/>
    <axis xyz="0 0 -1"/>
    <limit effort="10" lower="-0.785" upper="0.785" velocity="20"/>
  </joint>
  <!-- ===== TRANSMISSIONS FOR ACTUATED JOINTS ===== -->
  <!-- Wheel velocity transmissions -->
  <transmission name="fl_wheel_trans">
    <type>transmission_interface/SimpleTransmission</type>
    <joint name="fl_wheel_joint">
      <hardwareInterface>hardware_interface/VelocityJointInterface</hardwareInterface>
    </joint>
    <actuator name="fl_wheel_motor">
      <hardwareInterface>hardware_interface/VelocityJointInterface</hardwareInterface>
      <mechanicalReduction>1</mechanicalReduction>
    </actuator>
  </transmission>
  <transmission name="rl_wheel_trans">
    <type>transmission_interface/SimpleTransmission</type>
    <joint name="rl_wheel_joint">
      <hardwareInterface>hardware_interface/VelocityJointInterface</hardwareInterface>
    </joint>
    <actuator name="rl_wheel_motor">
      <hardwareInterface>hardware_interface/VelocityJointInterface</hardwareInterface>
      <mechanicalReduction>1</mechanicalReduction>
    </actuator>
  </transmission>
  <transmission name="fr_wheel_trans">
    <type>transmission_interface/SimpleTransmission</type>
    <joint name="fr_wheel_joint">
      <hardwareInterface>hardware_interface/VelocityJointInterface</hardwareInterface>
    </joint>
    <actuator name="fr_wheel_motor">
      <hardwareInterface>hardware_interface/VelocityJointInterface</hardwareInterface>
      <mechanicalReduction>1</mechanicalReduction>
    </actuator>
  </transmission>
  <transmission name="rr_wheel_trans">
    <type>transmission_interface/SimpleTransmission</type>
    <joint name="rr_wheel_joint">
      <hardwareInterface>hardware_interface/VelocityJointInterface</hardwareInterface>
    </joint>
    <actuator name="rr_wheel_motor">
      <hardwareInterface>hardware_interface/VelocityJointInterface</hardwareInterface>
      <mechanicalReduction>1</mechanicalReduction>
    </actuator>
  </transmission>
  <!-- Steering position transmissions -->
  <transmission name="steer_fl_trans">
    <type>transmission_interface/SimpleTransmission</type>
    <joint name="steer_fl_joint">
      <hardwareInterface>hardware_interface/PositionJointInterface</hardwareInterface>
    </joint>
    <actuator name="steer_fl_motor">
      <hardwareInterface>hardware_interface/PositionJointInterface</hardwareInterface>
      <mechanicalReduction>1</mechanicalReduction>
    </actuator>
  </transmission>
  <transmission name="steer_rl_trans">
    <type>transmission_interface/SimpleTransmission</type>
    <joint name="steer_rl_joint">
      <hardwareInterface>hardware_interface/PositionJointInterface</hardwareInterface>
    </joint>
    <actuator name="steer_rl_motor">
      <hardwareInterface>hardware_interface/PositionJointInterface</hardwareInterface>
      <mechanicalReduction>1</mechanicalReduction>
    </actuator>
  </transmission>
  <transmission name="steer_fr_trans">
    <type>transmission_interface/SimpleTransmission</type>
    <joint name="steer_fr_joint">
      <hardwareInterface>hardware_interface/PositionJointInterface</hardwareInterface>
    </joint>
    <actuator name="steer_fr_motor">
      <hardwareInterface>hardware_interface/PositionJointInterface</hardwareInterface>
      <mechanicalReduction>1</mechanicalReduction>
    </actuator>
  </transmission>
  <transmission name="steer_rr_trans">
    <type>transmission_interface/SimpleTransmission</type>
    <joint name="steer_rr_joint">
      <hardwareInterface>hardware_interface/PositionJointInterface</hardwareInterface>
    </joint>
    <actuator name="steer_rr_motor">
      <hardwareInterface>hardware_interface/PositionJointInterface</hardwareInterface>
      <mechanicalReduction>1</mechanicalReduction>
    </actuator>
  </transmission>
  <link name="turnbuckle_left">
    <inertial>
      <origin rpy="0 0 0" xyz="5.34219644405254E-05 -0.000100047522705149 3.94380414436846E-09"/>
      <mass value="0.00309472740252932"/>
      <inertia ixx="3.21656774622978E-06" ixy="-4.10495316029439E-10" ixz="3.51196526219277E-11" iyy="3.21711732254786E-06" iyz="-8.25530439188717E-11" izz="1.42977819273037E-08"/>
    </inertial>
    <visual>
      <origin rpy="0 0 0" xyz="0 0 0"/>
      <geometry>
        <mesh filename="package://rocker_description/meshes/turnbuckle_left.STL"/>
      </geometry>
      <material name="">
        <color rgba="0.792156862745098 0.819607843137255 0.933333333333333 1"/>
      </material>
    </visual>
    <collision>
      <origin rpy="0 0 0" xyz="0 0 0"/>
      <geometry>
        <mesh filename="package://rocker_description/meshes/turnbuckle_left.STL"/>
      </geometry>
    </collision>
  </link>
  <joint name="turnbuckle_left_joint" type="revolute">
    <origin rpy="1.5708 0 1.5708" xyz="-0.04188 0.111 0.022998"/>
    <parent link="diff_link"/>
    <child link="turnbuckle_left"/>
    <axis xyz="0 0 -1"/>
    <limit effort="10" lower="-0.1" upper="0.1" velocity="20"/>
  </joint>
  <link name="turnbuckle_right">
    <inertial>
      <origin rpy="0 0 0" xyz="-2.95876236215131E-05 -2.45605062221266E-05 1.0037929376594E-09"/>
      <mass value="0.00309472738645889"/>
      <inertia ixx="3.21674519059412E-06" ixy="-5.19742068643782E-10" ixz="-6.77215920633861E-11" iyy="3.21693988199051E-06" iyz="-1.96901591552011E-11" izz="1.42977779775118E-08"/>
    </inertial>
    <visual>
      <origin rpy="0 0 0" xyz="0 0 0"/>
      <geometry>
        <mesh filename="package://rocker_description/meshes/turnbuckle_right.STL"/>
      </geometry>
      <material name="">
        <color rgba="0.792156862745098 0.819607843137255 0.933333333333333 1"/>
      </material>
    </visual>
    <collision>
      <origin rpy="0 0 0" xyz="0 0 0"/>
      <geometry>
        <mesh filename="package://rocker_description/meshes/turnbuckle_right.STL"/>
      </geometry>
    </collision>
  </link>
  <joint name="turnbuckle_right_joint" type="revolute">
    <origin rpy="1.5708 0 1.5708" xyz="-0.04188 -0.111 0.022998"/>
    <parent link="diff_link"/>
    <child link="turnbuckle_right"/>
    <axis xyz="0 0 -1"/>
    <limit effort="10" lower="-0.1" upper="0.1" velocity="20"/>
  </joint>
</robot>
