<?xml version="1.0" encoding="utf-8"?>
<!-- This URDF was automatically created by SolidWorks to URDF Exporter! Originally created by Stephen Brawner (brawner@gmail.com) 
     Commit Version: 1.6.0-4-g7f85cfe  Build Version: 1.6.7995.38578
     For more information, please see http://wiki.ros.org/sw_urdf_exporter -->
<robot name="rocker" xmlns:xacro="http://ros.org/wiki/xacro">
  <!-- Start GZ or Ignition depending on ROS 2 Version -->
  <xacro:arg name="is_ignition" default="true"/>

  <!-- Include Gazebo Parameters -->
  <xacro:include filename="$(find rocker_description)/urdf/rocker_gazebo.xacro" />
  <!-- Include control -->
  <xacro:include filename="$(find rocker_description)/urdf/rocker_ros2_control.xacro"/>
  <link
    name="base_link">
    <inertial>
      <origin
        xyz="0.0036529 -1.0215E-05 0.02903"
        rpy="0 0 0" />
      <mass
        value="3.2518" />
      <inertia
        ixx="0.012194"
        ixy="-4.5489E-11"
        ixz="-1.2673E-05"
        iyy="0.0094514"
        iyz="-9.282E-10"
        izz="0.019133" />
    </inertial>
    <visual>
      <origin
        xyz="0 0 0"
        rpy="0 0 0" />
      <geometry>
        <mesh
          filename="package://rocker_description/meshes/base_link.STL" />
      </geometry>
      <material
        name="">
        <color
          rgba="1 0 0 1" />
      </material>
    </visual>
    <collision>
      <origin
        xyz="0 0 0"
        rpy="0 0 0" />
      <geometry>
        <mesh
          filename="package://rocker_description/meshes/base_link.STL" />
      </geometry>
    </collision>
  </link>
  <link
    name="rocker_left">
    <inertial>
      <origin
        xyz="-0.0059628 0.019312 0.0082178"
        rpy="0 0 0" />
      <mass
        value="0.54828" />
      <inertia
        ixx="0.00016071"
        ixy="-1.183E-05"
        ixz="4.6534E-08"
        iyy="0.0014571"
        iyz="2.3855E-06"
        izz="0.0015011" />
    </inertial>
    <visual>
      <origin
        xyz="0 0 0"
        rpy="0 0 0" />
      <geometry>
        <mesh
          filename="package://rocker_description/meshes/rocker_left.STL" />
      </geometry>
      <material
        name="">
        <color
          rgba="0 0.4 0 1" />
      </material>
    </visual>
    <collision>
      <origin
        xyz="0 0 0"
        rpy="0 0 0" />
      <geometry>
        <mesh
          filename="package://rocker_description/meshes/rocker_left.STL" />
      </geometry>
    </collision>
  </link>
  <joint
    name="rocker_left_joint"
    type="revolute">
    <origin
      xyz="-0.00300007366280326 0.139989762643875 0.00599815142431871"
      rpy="-1.5707963267949 0 0" />
    <parent
      link="base_link" />
    <child
      link="rocker_left" />
    <axis
      xyz="0 0 -1" />
    <limit
      lower="-0.785"
      upper="0.785"
      effort="10"
      velocity="20" />
  </joint>
  <link
    name="steer_fl">
    <inertial>
      <origin
        xyz="0.000519302806489763 0.00116147489574497 -0.072249011838569"
        rpy="0 0 0" />
      <mass
        value="0.0538768873270146" />
      <inertia
        ixx="1.72835692633752E-05"
        ixy="1.86524259779789E-10"
        ixz="1.22947445955912E-09"
        iyy="1.2650499733089E-05"
        iyz="1.0347992030602E-12"
        izz="1.0115174825469E-05" />
    </inertial>
    <visual>
      <origin
        xyz="0 0 0"
        rpy="0 0 0" />
      <geometry>
        <mesh
          filename="package://rocker_description/meshes/steer_fl.STL" />
      </geometry>
      <material
        name="">
        <color
          rgba="0.752941176470588 0.752941176470588 0.752941176470588 1" />
      </material>
    </visual>
    <collision>
      <origin
        xyz="0 0 0"
        rpy="0 0 0" />
      <geometry>
        <mesh
          filename="package://rocker_description/meshes/steer_fl.STL" />
      </geometry>
    </collision>
  </link>
  <joint
    name="steer_fl_joint"
    type="revolute">
    <origin
      xyz="0.109493624388031 0.03794110103799 0.0465656792826112"
      rpy="1.5707963267949 0 0" />
    <parent
      link="rocker_left" />
    <child
      link="steer_fl" />
    <axis
      xyz="0 0 -1" />
    <limit
      lower="-3.14"
      upper="3.14"
      effort="10"
      velocity="20" />
  </joint>
  <link
    name="fl_wheel">
    <inertial>
      <origin
        xyz="0.002099 -0.0019395 -0.028409"
        rpy="0 0 0" />
      <mass
        value="0.13017" />
      <inertia
        ixx="0.00012478"
        ixy="-7.5675E-12"
        ixz="-1.0928E-11"
        iyy="0.00012478"
        iyz="-2.364E-12"
        izz="0.00023467" />
    </inertial>
    <visual>
      <origin
        xyz="0 0 0"
        rpy="0 0 0" />
      <geometry>
        <mesh
          filename="package://rocker_description/meshes/fl_wheel.STL" />
      </geometry>
      <material
        name="">
        <color
          rgba="0 0 0 1" />
      </material>
    </visual>
    <collision>
      <origin
        xyz="0 0 0"
        rpy="0 0 0" />
      <geometry>
        <mesh
          filename="package://rocker_description/meshes/fl_wheel.STL" />
      </geometry>
    </collision>
  </link>
  <joint
    name="fl_wheel_joint"
    type="continuous">
    <origin
      xyz="-0.0015781170593388 0.0908967088232542 -0.0809547532967621"
      rpy="-1.5707963267949 0 0" />
    <parent
      link="steer_fl" />
    <child
      link="fl_wheel" />
    <axis
      xyz="0 0 -1" />
    <limit
      lower="-10"
      upper="10"
      effort="10"
      velocity="100" />
  </joint>
  <link
    name="steer_rl">
    <inertial>
      <origin
        xyz="0.000484941569044396 0.00116147486494456 -0.0761644406147317"
        rpy="0 0 0" />
      <mass
        value="0.053876887039627" />
      <inertia
        ixx="1.72835692580122E-05"
        ixy="1.86520191057726E-10"
        ixz="1.22945286982955E-09"
        iyy="1.26504997081888E-05"
        iyz="1.03201975349808E-12"
        izz="1.01151748056035E-05" />
    </inertial>
    <visual>
      <origin
        xyz="0 0 0"
        rpy="0 0 0" />
      <geometry>
        <mesh
          filename="package://rocker_description/meshes/steer_rl.STL" />
      </geometry>
      <material
        name="">
        <color
          rgba="0.752941176470588 0.752941176470588 0.752941176470588 1" />
      </material>
    </visual>
    <collision>
      <origin
        xyz="0 0 0"
        rpy="0 0 0" />
      <geometry>
        <mesh
          filename="package://rocker_description/meshes/steer_rl.STL" />
      </geometry>
    </collision>
  </link>
  <joint
    name="steer_rl_joint"
    type="revolute">
    <origin
      xyz="-0.110472012747799 0.0340528521482858 0.0465656792826093"
      rpy="1.5707963267949 0 0" />
    <parent
      link="rocker_left" />
    <child
      link="steer_rl" />
    <axis
      xyz="0 0 -1" />
    <limit
      lower="-3.14"
      upper="3.14"
      effort="10"
      velocity="20" />
  </joint>
  <link
    name="rl_wheel">
    <inertial>
      <origin
        xyz="0.0020646 0.001976 -0.028409"
        rpy="0 0 0" />
      <mass
        value="0.13017" />
      <inertia
        ixx="0.00012478"
        ixy="3.8397E-11"
        ixz="1.7184E-12"
        iyy="0.00012478"
        iyz="1.1048E-11"
        izz="0.00023467" />
    </inertial>
    <visual>
      <origin
        xyz="0 0 0"
        rpy="0 0 0" />
      <geometry>
        <mesh
          filename="package://rocker_description/meshes/rl_wheel.STL" />
      </geometry>
      <material
        name="">
        <color
          rgba="0 0 0 1" />
      </material>
    </visual>
    <collision>
      <origin
        xyz="0 0 0"
        rpy="0 0 0" />
      <geometry>
        <mesh
          filename="package://rocker_description/meshes/rl_wheel.STL" />
      </geometry>
    </collision>
  </link>
  <joint
    name="rl_wheel_joint"
    type="continuous">
    <origin
      xyz="-0.00157811705934295 0.0908967088232554 -0.0809547532967675"
      rpy="-1.5707963267949 0 0" />
    <parent
      link="steer_rl" />
    <child
      link="rl_wheel" />
    <axis
      xyz="0 0 -1" />
    <limit
      lower="-10"
      upper="10"
      effort="10"
      velocity="100" />
  </joint>
  <link
    name="rocker_right">
    <inertial>
      <origin
        xyz="-0.0059629 -0.019312 0.0081798"
        rpy="0 0 0" />
      <mass
        value="0.54828" />
      <inertia
        ixx="0.00016071"
        ixy="1.17E-05"
        ixz="-4.5953E-08"
        iyy="0.0014571"
        iyz="-2.3178E-06"
        izz="0.0015011" />
    </inertial>
    <visual>
      <origin
        xyz="0 0 0"
        rpy="0 0 0" />
      <geometry>
        <mesh
          filename="package://rocker_description/meshes/rocker_right.STL" />
      </geometry>
      <material
        name="">
        <color
          rgba="0 0.4 0 1" />
      </material>
    </visual>
    <collision>
      <origin
        xyz="0 0 0"
        rpy="0 0 0" />
      <geometry>
        <mesh
          filename="package://rocker_description/meshes/rocker_right.STL" />
      </geometry>
    </collision>
  </link>
  <joint
    name="rocker_right_joint"
    type="revolute">
    <origin
      xyz="-0.00300007366280228 -0.140010237356125 0.00599815142431871"
      rpy="1.5707963267949 0 0" />
    <parent
      link="base_link" />
    <child
      link="rocker_right" />
    <axis
      xyz="0 0 -1" />
    <limit
      lower="-0.785"
      upper="0.785"
      effort="10"
      velocity="20" />
  </joint>
  <link
    name="steer_fr">
    <inertial>
      <origin
        xyz="0.000814806464579348 -0.0011614749039093 -0.0722542108542284"
        rpy="0 0 0" />
      <mass
        value="0.0538768875909339" />
      <inertia
        ixx="1.7283569439176E-05"
        ixy="1.86519220841325E-10"
        ixz="5.41777362598005E-10"
        iyy="1.26504997368065E-05"
        iyz="-9.95471491964069E-13"
        izz="1.01151746572533E-05" />
    </inertial>
    <visual>
      <origin
        xyz="0 0 0"
        rpy="0 0 0" />
      <geometry>
        <mesh
          filename="package://rocker_description/meshes/steer_fr.STL" />
      </geometry>
      <material
        name="">
        <color
          rgba="0.752941176470588 0.752941176470588 0.752941176470588 1" />
      </material>
    </visual>
    <collision>
      <origin
        xyz="0 0 0"
        rpy="0 0 0" />
      <geometry>
        <mesh
          filename="package://rocker_description/meshes/steer_fr.STL" />
      </geometry>
    </collision>
  </link>
  <joint
    name="steer_fr_joint"
    type="revolute">
    <origin
      xyz="0.109199494929351 -0.0379359018234412 0.0464809030708809"
      rpy="-1.5707963267949 0 0" />
    <parent
      link="rocker_right" />
    <child
      link="steer_fr" />
    <axis
      xyz="0 0 -1" />
    <limit
      lower="-3.14"
      upper="3.14"
      effort="10"
      velocity="20" />
  </joint>
  <link
    name="fr_wheel">
    <inertial>
      <origin
        xyz="0.002099 -0.0019395 0.028409"
        rpy="0 0 0" />
      <mass
        value="0.13017" />
      <inertia
        ixx="0.00012478"
        ixy="-4.1966E-11"
        ixz="2.4004E-12"
        iyy="0.00012478"
        iyz="-1.092E-11"
        izz="0.00023467" />
    </inertial>
    <visual>
      <origin
        xyz="0 0 0"
        rpy="0 0 0" />
      <geometry>
        <mesh
          filename="package://rocker_description/meshes/fr_wheel.STL" />
      </geometry>
      <material
        name="">
        <color
          rgba="0 0 0 1" />
      </material>
    </visual>
    <collision>
      <origin
        xyz="0 0 0"
        rpy="0 0 0" />
      <geometry>
        <mesh
          filename="package://rocker_description/meshes/fr_wheel.STL" />
      </geometry>
    </collision>
  </link>
  <joint
    name="fr_wheel_joint"
    type="continuous">
    <origin
      xyz="-0.00128398760065623 -0.0908967088232549 -0.0809599525113137"
      rpy="-1.5707963267949 0 0" />
    <parent
      link="steer_fr" />
    <child
      link="fr_wheel" />
    <axis
      xyz="0 0 -1" />
    <limit
      lower="-10"
      upper="10"
      effort="10"
      velocity="100" />
  </joint>
  <link
    name="steer_rr">
    <inertial>
      <origin
        xyz="0.000780445293958792 -0.00116147482875609 -0.0761696396391992"
        rpy="0 0 0" />
      <mass
        value="0.053876886751126" />
      <inertia
        ixx="1.72835694160757E-05"
        ixy="1.86521749794259E-10"
        ixz="5.41788240519471E-10"
        iyy="1.26504996855531E-05"
        iyz="-9.90981572115684E-13"
        izz="1.0115174625481E-05" />
    </inertial>
    <visual>
      <origin
        xyz="0 0 0"
        rpy="0 0 0" />
      <geometry>
        <mesh
          filename="package://rocker_description/meshes/steer_rr.STL" />
      </geometry>
      <material
        name="">
        <color
          rgba="0.752941176470588 0.752941176470588 0.752941176470588 1" />
      </material>
    </visual>
    <collision>
      <origin
        xyz="0 0 0"
        rpy="0 0 0" />
      <geometry>
        <mesh
          filename="package://rocker_description/meshes/steer_rr.STL" />
      </geometry>
    </collision>
  </link>
  <joint
    name="steer_rr_joint"
    type="revolute">
    <origin
      xyz="-0.11076614220648 -0.0340476529337355 0.0464809030708823"
      rpy="-1.5707963267949 0 0" />
    <parent
      link="rocker_right" />
    <child
      link="steer_rr" />
    <axis
      xyz="0 0 -1" />
    <limit
      lower="-3.14"
      upper="3.14"
      effort="10"
      velocity="20" />
  </joint>
  <link
    name="rr_wheel">
    <inertial>
      <origin
        xyz="0.0020646 0.001976 0.028409"
        rpy="0 0 0" />
      <mass
        value="0.13017" />
      <inertia
        ixx="0.00012478"
        ixy="-2.6947E-11"
        ixz="-2.0987E-14"
        iyy="0.00012478"
        iyz="-1.1181E-11"
        izz="0.00023467" />
    </inertial>
    <visual>
      <origin
        xyz="0 0 0"
        rpy="0 0 0" />
      <geometry>
        <mesh
          filename="package://rocker_description/meshes/rr_wheel.STL" />
      </geometry>
      <material
        name="">
        <color
          rgba="0 0 0 1" />
      </material>
    </visual>
    <collision>
      <origin
        xyz="0 0 0"
        rpy="0 0 0" />
      <geometry>
        <mesh
          filename="package://rocker_description/meshes/rr_wheel.STL" />
      </geometry>
    </collision>
  </link>
  <joint
    name="rr_wheel_joint"
    type="continuous">
    <origin
      xyz="-0.00128398760065685 -0.0908967088232536 -0.0809599525113122"
      rpy="-1.5707963267949 0 0" />
    <parent
      link="steer_rr" />
    <child
      link="rr_wheel" />
    <axis
      xyz="0 0 -1" />
    <limit
      lower="-10"
      upper="10"
      effort="10"
      velocity="100" />
  </joint>
  <link
    name="clink_left">
    <inertial>
      <origin
        xyz="-6.93889390390723E-16 -1.33226762955019E-15 6.02295990859147E-15"
        rpy="0 0 0" />
      <mass
        value="0.00245633275602552" />
      <inertia
        ixx="3.2073073695252E-06"
        ixy="4.03961406958447E-25"
        ixz="1.41020144713961E-20"
        iyy="3.20730736632451E-06"
        iyz="-1.01197867219257E-10"
        izz="7.6760430632636E-09" />
    </inertial>
    <visual>
      <origin
        xyz="0 0 0"
        rpy="0 0 0" />
      <geometry>
        <mesh
          filename="package://rocker_description/meshes/clink_left.STL" />
      </geometry>
      <material
        name="">
        <color
          rgba="0.792156862745098 0.819607843137255 0.933333333333333 1" />
      </material>
    </visual>
    <collision>
      <origin
        xyz="0 0 0"
        rpy="0 0 0" />
      <geometry>
        <mesh
          filename="package://rocker_description/meshes/clink_left.STL" />
      </geometry>
    </collision>
  </link>
  <joint
    name="clink_left_joint"
    type="continuous">
    <origin
      xyz="0.03012 0.11099 0.088996"
      rpy="1.5708 0 1.5708" />
    <parent
      link="base_link" />
    <child
      link="clink_left" />
    <axis
      xyz="0 0 -1" />
    <limit
      lower="-10"
      upper="10"
      effort="10"
      velocity="20" />
  </joint>
  <link
    name="clink_right">
    <inertial>
      <origin
        xyz="-6.93889390390723E-18 0 -2.77555756156289E-17"
        rpy="0 0 0" />
      <mass
        value="0.00245633275602552" />
      <inertia
        ixx="3.2073073695252E-06"
        ixy="8.82223666204742E-25"
        ixz="3.37475697589242E-20"
        iyy="3.20730736632452E-06"
        iyz="-1.01197867165641E-10"
        izz="7.6760430632636E-09" />
    </inertial>
    <visual>
      <origin
        xyz="0 0 0"
        rpy="0 0 0" />
      <geometry>
        <mesh
          filename="package://rocker_description/meshes/clink_right.STL" />
      </geometry>
      <material
        name="">
        <color
          rgba="0.792156862745098 0.819607843137255 0.933333333333333 1" />
      </material>
    </visual>
    <collision>
      <origin
        xyz="0 0 0"
        rpy="0 0 0" />
      <geometry>
        <mesh
          filename="package://rocker_description/meshes/clink_right.STL" />
      </geometry>
    </collision>
  </link>
  <joint
    name="clink_right_joint"
    type="continuous">
    <origin
      xyz="0.03012 -0.11101 0.088996"
      rpy="1.5708 0 1.5708" />
    <parent
      link="base_link" />
    <child
      link="clink_right" />
    <axis
      xyz="0 0 -1" />
    <limit
      lower="-10"
      upper="10"
      effort="10"
      velocity="20" />
  </joint>

        <!-- ===== TRANSMISSIONS FOR ACTUATED JOINTS ===== -->
  
  <!-- Wheel velocity transmissions -->
  <transmission name="fl_wheel_trans">
    <type>transmission_interface/SimpleTransmission</type>
    <joint name="fl_wheel_joint">
      <hardwareInterface>hardware_interface/VelocityJointInterface</hardwareInterface>
    </joint>
    <actuator name="fl_wheel_motor">
      <hardwareInterface>hardware_interface/VelocityJointInterface</hardwareInterface>
      <mechanicalReduction>1</mechanicalReduction>
    </actuator>
  </transmission>

  <transmission name="rl_wheel_trans">
    <type>transmission_interface/SimpleTransmission</type>
    <joint name="rl_wheel_joint">
      <hardwareInterface>hardware_interface/VelocityJointInterface</hardwareInterface>
    </joint>
    <actuator name="rl_wheel_motor">
      <hardwareInterface>hardware_interface/VelocityJointInterface</hardwareInterface>
      <mechanicalReduction>1</mechanicalReduction>
    </actuator>
  </transmission>

  <transmission name="fr_wheel_trans">
    <type>transmission_interface/SimpleTransmission</type>
    <joint name="fr_wheel_joint">
      <hardwareInterface>hardware_interface/VelocityJointInterface</hardwareInterface>
    </joint>
    <actuator name="fr_wheel_motor">
      <hardwareInterface>hardware_interface/VelocityJointInterface</hardwareInterface>
      <mechanicalReduction>1</mechanicalReduction>
    </actuator>
  </transmission>

  <transmission name="rr_wheel_trans">
    <type>transmission_interface/SimpleTransmission</type>
    <joint name="rr_wheel_joint">
      <hardwareInterface>hardware_interface/VelocityJointInterface</hardwareInterface>
    </joint>
    <actuator name="rr_wheel_motor">
      <hardwareInterface>hardware_interface/VelocityJointInterface</hardwareInterface>
      <mechanicalReduction>1</mechanicalReduction>
    </actuator>
  </transmission>

  <!-- Steering position transmissions -->
  <transmission name="steer_fl_trans">
    <type>transmission_interface/SimpleTransmission</type>
    <joint name="steer_fl_joint">
      <hardwareInterface>hardware_interface/PositionJointInterface</hardwareInterface>
    </joint>
    <actuator name="steer_fl_motor">
      <hardwareInterface>hardware_interface/PositionJointInterface</hardwareInterface>
      <mechanicalReduction>1</mechanicalReduction>
    </actuator>
  </transmission>

  <transmission name="steer_rl_trans">
    <type>transmission_interface/SimpleTransmission</type>
    <joint name="steer_rl_joint">
      <hardwareInterface>hardware_interface/PositionJointInterface</hardwareInterface>
    </joint>
    <actuator name="steer_rl_motor">
      <hardwareInterface>hardware_interface/PositionJointInterface</hardwareInterface>
      <mechanicalReduction>1</mechanicalReduction>
    </actuator>
  </transmission>

  <transmission name="steer_fr_trans">
    <type>transmission_interface/SimpleTransmission</type>
    <joint name="steer_fr_joint">
      <hardwareInterface>hardware_interface/PositionJointInterface</hardwareInterface>
    </joint>
    <actuator name="steer_fr_motor">
      <hardwareInterface>hardware_interface/PositionJointInterface</hardwareInterface>
      <mechanicalReduction>1</mechanicalReduction>
    </actuator>
  </transmission>

  <transmission name="steer_rr_trans">
    <type>transmission_interface/SimpleTransmission</type>
    <joint name="steer_rr_joint">
      <hardwareInterface>hardware_interface/PositionJointInterface</hardwareInterface>
    </joint>
    <actuator name="steer_rr_motor">
      <hardwareInterface>hardware_interface/PositionJointInterface</hardwareInterface>
      <mechanicalReduction>1</mechanicalReduction>
    </actuator>
  </transmission>
</robot>