<?xml version="1.0" encoding="utf-8"?>
<!-- This URDF was automatically created by SolidWorks to URDF Exporter! Originally created by Stephen Brawner (brawner@gmail.com) 
     Commit Version: 1.6.0-4-g7f85cfe  Build Version: 1.6.7995.38578
     For more information, please see http://wiki.ros.org/sw_urdf_exporter -->
<robot name="rocker" xmlns:xacro="http://ros.org/wiki/xacro">
  <!-- Start GZ or Ignition depending on ROS 2 Version -->
  <xacro:arg name="is_ignition" default="true"/>

  <!-- Include Gazebo Parameters -->
  <xacro:include filename="$(find rocker_description)/urdf/rocker_gazebo.xacro" />
  <!-- Include control -->
  <xacro:include filename="$(find rocker_description)/urdf/rocker_ros2_control.xacro"/>
  
  <link
    name="base_link">
    <inertial>
      <origin
        xyz="-0.0029178 -1.0243E-05 0.026001"
        rpy="0 0 0" />
      <mass
        value="3.0355" />
      <inertia
        ixx="0.011434"
        ixy="8.2789E-18"
        ixz="-1.2087E-05"
        iyy="0.0094299"
        iyz="-3.1877E-20"
        izz="0.018372" />
    </inertial>
    <visual>
      <origin
        xyz="0 0 0"
        rpy="0 0 0" />
      <geometry>
        <mesh
          filename="package://rocker_description/meshes/base_link.STL" />
      </geometry>
      <material
        name="">
        <color
          rgba="1 0 0 1" />
      </material>
    </visual>
    <collision>
      <origin
        xyz="0 0 0"
        rpy="0 0 0" />
      <geometry>
        <mesh
          filename="package://rocker_description/meshes/base_link.STL" />
      </geometry>
    </collision>
  </link>
  <link
    name="diff_link">
    <inertial>
      <origin
        xyz="0.0236047033494922 3.38568454466559E-07 0.00680399174365073"
        rpy="0 0 0" />
      <mass
        value="0.218473302594947" />
      <inertia
        ixx="0.000709218973632844"
        ixy="-4.54869495674156E-11"
        ixz="-5.80923680880486E-07"
        iyy="2.67923062348123E-05"
        iyz="-9.28184396595003E-10"
        izz="0.000717476916941679" />
    </inertial>
    <visual>
      <origin
        xyz="0 0 0"
        rpy="0 0 0" />
      <geometry>
        <mesh
          filename="package://rocker_description/meshes/diff_link.STL" />
      </geometry>
      <material
        name="">
        <color
          rgba="0.752941176470588 0.752941176470588 0.752941176470588 1" />
      </material>
    </visual>
    <collision>
      <origin
        xyz="0 0 0"
        rpy="0 0 0" />
      <geometry>
        <mesh
          filename="package://rocker_description/meshes/diff_link.STL" />
      </geometry>
    </collision>
  </link>
  <joint
    name="diff_link_joint"
    type="revolute">
    <origin
      xyz="0.071998 -1.0243E-05 0.066001"
      rpy="0 0 0" />
    <parent
      link="base_link" />
    <child
      link="diff_link" />
    <axis
      xyz="0 0 -1" />
    <limit
      lower="-0.785"
      upper="0.785"
      effort="10"
      velocity="20" />
  </joint>
  <link
    name="T_left">
    <inertial>
      <origin
        xyz="-0.00596279656055823 0.0193116567400055 0.0182177510881137"
        rpy="0 0 0" />
      <mass
        value="0.548279468054" />
      <inertia
        ixx="0.000160712183061877"
        ixy="-1.1829517489236E-05"
        ixz="4.65340927469138E-08"
        iyy="0.00145712336718833"
        iyz="2.38546499162641E-06"
        izz="0.00150112676275928" />
    </inertial>
    <visual>
      <origin
        xyz="0 0 0"
        rpy="0 0 0" />
      <geometry>
        <mesh
          filename="package://rocker_description/meshes/T_left.STL" />
      </geometry>
      <material
        name="">
        <color
          rgba="0.752941176470588 0.752941176470588 0.752941176470588 1" />
      </material>
    </visual>
    <collision>
      <origin
        xyz="0 0 0"
        rpy="0 0 0" />
      <geometry>
        <mesh
          filename="package://rocker_description/meshes/T_left.STL" />
      </geometry>
    </collision>
  </link>
  <joint
    name="T_left_joint"
    type="revolute">
    <origin
      xyz="-0.0750000000000018 0.129999999999997 -0.0599999999999974"
      rpy="-1.5707963267949 0 0" />
    <parent
      link="diff_link" />
    <child
      link="T_left" />
    <axis
      xyz="0 0 -1" />
    <limit
      lower="-0.785"
      upper="0.785"
      effort="10"
      velocity="20" />
  </joint>
  <link
    name="steer_fl">
    <inertial>
      <origin
        xyz="-0.000138607396474422 0.0211614748792864 -0.0742037212781577"
        rpy="0 0 0" />
      <mass
        value="0.0538768872920871" />
      <inertia
        ixx="1.72835692626109E-05"
        ixy="1.86515416826833E-10"
        ixz="1.22948666319558E-09"
        iyy="1.26504997120413E-05"
        iyz="1.03710843764432E-12"
        izz="1.01151748078112E-05" />
    </inertial>
    <visual>
      <origin
        xyz="0 0 0"
        rpy="0 0 0" />
      <geometry>
        <mesh
          filename="package://rocker_description/meshes/steer_fl.STL" />
      </geometry>
      <material
        name="">
        <color
          rgba="0.752941176470588 0.752941176470588 0.752941176470588 1" />
      </material>
    </visual>
    <collision>
      <origin
        xyz="0 0 0"
        rpy="0 0 0" />
      <geometry>
        <mesh
          filename="package://rocker_description/meshes/steer_fl.STL" />
      </geometry>
    </collision>
  </link>
  <joint
    name="steer_fl_joint"
    type="revolute">
    <origin
      xyz="0.110151534483122 0.0359863916031299 0.0365656792826139"
      rpy="1.5707963267949 0 0" />
    <parent
      link="T_left" />
    <child
      link="steer_fl" />
    <axis
      xyz="0 0 -1" />
    <limit
      lower="-3.14"
      upper="3.14"
      effort="10"
      velocity="20" />
  </joint>
  <link
    name="fl_wheel">
    <inertial>
      <origin
        xyz="1.69573641517484E-08 -7.54815843162504E-09 -0.00840874583108248"
        rpy="0 0 0" />
      <mass
        value="0.13017290647518" />
      <inertia
        ixx="0.000124778074397082"
        ixy="-7.56745177284866E-12"
        ixz="-1.0927757268495E-11"
        iyy="0.000124777976595369"
        iyz="-2.36402552332323E-12"
        izz="0.000234671292019044" />
    </inertial>
    <visual>
      <origin
        xyz="0 0 0"
        rpy="0 0 0" />
      <geometry>
        <mesh
          filename="package://rocker_description/meshes/fl_wheel.STL" />
      </geometry>
      <material
        name="">
        <color
          rgba="0.792156862745098 0.819607843137255 0.933333333333333 1" />
      </material>
    </visual>
    <collision>
      <origin
        xyz="0 0 0"
        rpy="0 0 0" />
      <geometry>
        <mesh
          filename="package://rocker_description/meshes/fl_wheel.STL" />
      </geometry>
    </collision>
  </link>
  <joint
    name="fl_wheel_joint"
    type="continuous">
    <origin
      xyz="-0.000137084263775206 0.0908967088232522 -0.0809700175540105"
      rpy="-1.5707963267949 0 0" />
    <parent
      link="steer_fl" />
    <child
      link="fl_wheel" />
    <axis
      xyz="0 0 -1" />
    <limit
      lower="-10"
      upper="10"
      effort="10"
      velocity="100" />
  </joint>
  <link
    name="steer_rl">
    <inertial>
      <origin
        xyz="-0.000138607285511289 0.0211614748181154 -0.0742037209979592"
        rpy="0 0 0" />
      <mass
        value="0.0538768866301723" />
      <inertia
        ixx="1.72835692098332E-05"
        ixy="1.86529950289799E-10"
        ixz="1.22949485862317E-09"
        iyy="1.2650499668671E-05"
        iyz="1.05181708221559E-12"
        izz="1.01151748145831E-05" />
    </inertial>
    <visual>
      <origin
        xyz="0 0 0"
        rpy="0 0 0" />
      <geometry>
        <mesh
          filename="package://rocker_description/meshes/steer_rl.STL" />
      </geometry>
      <material
        name="">
        <color
          rgba="0.752941176470588 0.752941176470588 0.752941176470588 1" />
      </material>
    </visual>
    <collision>
      <origin
        xyz="0 0 0"
        rpy="0 0 0" />
      <geometry>
        <mesh
          filename="package://rocker_description/meshes/steer_rl.STL" />
      </geometry>
    </collision>
  </link>
  <joint
    name="steer_rl_joint"
    type="revolute">
    <origin
      xyz="-0.109848463837903 0.036013571503488 0.0365656792825895"
      rpy="1.5707963267949 0 0" />
    <parent
      link="T_left" />
    <child
      link="steer_rl" />
    <axis
      xyz="0 0 -1" />
    <limit
      lower="3.14"
      upper="3.14"
      effort="10"
      velocity="20" />
  </joint>
  <link
    name="rl_wheel">
    <inertial>
      <origin
        xyz="-1.31347291203177E-08 -1.3115099187222E-08 -0.00840874583108259"
        rpy="0 0 0" />
      <mass
        value="0.130172906475179" />
      <inertia
        ixx="0.000124777994283405"
        ixy="3.83968737472708E-11"
        ixz="1.71836063818701E-12"
        iyy="0.000124778056709046"
        iyz="1.10477040437135E-11"
        izz="0.000234671292019043" />
    </inertial>
    <visual>
      <origin
        xyz="0 0 0"
        rpy="0 0 0" />
      <geometry>
        <mesh
          filename="package://rocker_description/meshes/rl_wheel.STL" />
      </geometry>
      <material
        name="">
        <color
          rgba="0.792156862745098 0.819607843137255 0.933333333333333 1" />
      </material>
    </visual>
    <collision>
      <origin
        xyz="0 0 0"
        rpy="0 0 0" />
      <geometry>
        <mesh
          filename="package://rocker_description/meshes/rl_wheel.STL" />
      </geometry>
    </collision>
  </link>
  <joint
    name="rl_wheel_joint"
    type="continuous">
    <origin
      xyz="-0.000137084263778026 0.0908967088232761 -0.0809700175540202"
      rpy="-1.5707963267949 0 0" />
    <parent
      link="steer_rl" />
    <child
      link="rl_wheel" />
    <axis
      xyz="0 0 -1" />
    <limit
      lower="-10"
      upper="10"
      effort="10"
      velocity="100" />
  </joint>
  <link
    name="T_right">
    <inertial>
      <origin
        xyz="-0.00596288576987961 -0.0193116567457551 0.0181797727236157"
        rpy="0 0 0" />
      <mass
        value="0.548279467988765" />
      <inertia
        ixx="0.000160712214920952"
        ixy="1.17004377186215E-05"
        ixz="-4.5953040246728E-08"
        iyy="0.00145712333528735"
        iyz="-2.31782017688939E-06"
        izz="0.00150112676271101" />
    </inertial>
    <visual>
      <origin
        xyz="0 0 0"
        rpy="0 0 0" />
      <geometry>
        <mesh
          filename="package://rocker_description/meshes/T_right.STL" />
      </geometry>
      <material
        name="">
        <color
          rgba="0.752941176470588 0.752941176470588 0.752941176470588 1" />
      </material>
    </visual>
    <collision>
      <origin
        xyz="0 0 0"
        rpy="0 0 0" />
      <geometry>
        <mesh
          filename="package://rocker_description/meshes/T_right.STL" />
      </geometry>
    </collision>
  </link>
  <joint
    name="T_right_joint"
    type="revolute">
    <origin
      xyz="-0.0750000000000008 -0.130000000000003 -0.0599999999999974"
      rpy="1.5707963267949 0 0" />
    <parent
      link="diff_link" />
    <child
      link="T_right" />
    <axis
      xyz="0 0 -1" />
    <limit
      lower="-0.785"
      upper="0.785"
      effort="10"
      velocity="20" />
  </joint>
  <link
    name="steer_fr">
    <inertial>
      <origin
        xyz="0.000156942341989402 -0.0211614748804977 -0.0742036847520929"
        rpy="0 0 0" />
      <mass
        value="0.0538768874213247" />
      <inertia
        ixx="1.72835694212746E-05"
        ixy="1.86518764204385E-10"
        ixz="5.41782637895129E-10"
        iyy="1.26504997150358E-05"
        iyz="-9.90968342587935E-13"
        izz="1.01151746544475E-05" />
    </inertial>
    <visual>
      <origin
        xyz="0 0 0"
        rpy="0 0 0" />
      <geometry>
        <mesh
          filename="package://rocker_description/meshes/steer_fr.STL" />
      </geometry>
      <material
        name="">
        <color
          rgba="0.752941176470588 0.752941176470588 0.752941176470588 1" />
      </material>
    </visual>
    <collision>
      <origin
        xyz="0 0 0"
        rpy="0 0 0" />
      <geometry>
        <mesh
          filename="package://rocker_description/meshes/steer_fr.STL" />
      </geometry>
    </collision>
  </link>
  <joint
    name="steer_fr_joint"
    type="revolute">
    <origin
      xyz="0.109857359078023 -0.0359864279470623 0.0364809030708298"
      rpy="-1.5707963267949 0 0" />
    <parent
      link="T_right" />
    <child
      link="steer_fr" />
    <axis
      xyz="0 0 -1" />
    <limit
      lower="-3.14"
      upper="3.14"
      effort="10"
      velocity="20" />
  </joint>
  <link
    name="fr_wheel">
    <inertial>
      <origin
        xyz="1.39230255102873E-08 -1.22750265854621E-08 0.0084087458310832"
        rpy="0 0 0" />
      <mass
        value="0.13017290647518" />
      <inertia
        ixx="0.00012477799927836"
        ixy="-4.19664586325425E-11"
        ixz="2.40039555071648E-12"
        iyy="0.000124778051714091"
        iyz="-1.09198275501615E-11"
        izz="0.000234671292019044" />
    </inertial>
    <visual>
      <origin
        xyz="0 0 0"
        rpy="0 0 0" />
      <geometry>
        <mesh
          filename="package://rocker_description/meshes/fr_wheel.STL" />
      </geometry>
      <material
        name="">
        <color
          rgba="0.792156862745098 0.819607843137255 0.933333333333333 1" />
      </material>
    </visual>
    <collision>
      <origin
        xyz="0 0 0"
        rpy="0 0 0" />
      <geometry>
        <mesh
          filename="package://rocker_description/meshes/fr_wheel.STL" />
      </geometry>
    </collision>
  </link>
  <joint
    name="fr_wheel_joint"
    type="continuous">
    <origin
      xyz="0.000157091141341215 -0.0908967088233148 -0.0809699812101267"
      rpy="-1.5707963267949 0 0" />
    <parent
      link="steer_fr" />
    <child
      link="fr_wheel" />
    <axis
      xyz="0 0 -1" />
    <limit
      lower="-10"
      upper="10"
      effort="10"
      velocity="100" />
  </joint>
  <link
    name="steer_rr">
    <inertial>
      <origin
        xyz="0.000156942324142354 -0.0211614748347617 -0.0742036846636436"
        rpy="0 0 0" />
      <mass
        value="0.0538768867795237" />
      <inertia
        ixx="1.72835694167341E-05"
        ixy="1.86515908804649E-10"
        ixz="5.41777829608866E-10"
        iyy="1.26504996920115E-05"
        iyz="-9.95184188175488E-13"
        izz="1.01151746305982E-05" />
    </inertial>
    <visual>
      <origin
        xyz="0 0 0"
        rpy="0 0 0" />
      <geometry>
        <mesh
          filename="package://rocker_description/meshes/steer_rr.STL" />
      </geometry>
      <material
        name="">
        <color
          rgba="0.752941176470588 0.752941176470588 0.752941176470588 1" />
      </material>
    </visual>
    <collision>
      <origin
        xyz="0 0 0"
        rpy="0 0 0" />
      <geometry>
        <mesh
          filename="package://rocker_description/meshes/steer_rr.STL" />
      </geometry>
    </collision>
  </link>
  <joint
    name="steer_rr_joint"
    type="revolute">
    <origin
      xyz="-0.110142639243014 -0.0360136078473928 0.0364809030708942"
      rpy="-1.5707963267949 0 0" />
    <parent
      link="T_right" />
    <child
      link="steer_rr" />
    <axis
      xyz="0 0 -1" />
    <limit
      lower="-3.14"
      upper="3.14"
      effort="10"
      velocity="20" />
  </joint>
  <link
    name="rr_wheel">
    <inertial>
      <origin
        xyz="1.09348487885991E-08 -1.49985331862612E-08 0.00840874583108314"
        rpy="0 0 0" />
      <mass
        value="0.13017290647518" />
      <inertia
        ixx="0.00012477798399415"
        ixy="-2.69469454594134E-11"
        ixz="-2.09870081310354E-14"
        iyy="0.0001247780669983"
        iyz="-1.11805214099229E-11"
        izz="0.000234671292019043" />
    </inertial>
    <visual>
      <origin
        xyz="0 0 0"
        rpy="0 0 0" />
      <geometry>
        <mesh
          filename="package://rocker_description/meshes/rr_wheel.STL" />
      </geometry>
      <material
        name="">
        <color
          rgba="0.792156862745098 0.819607843137255 0.933333333333333 1" />
      </material>
    </visual>
    <collision>
      <origin
        xyz="0 0 0"
        rpy="0 0 0" />
      <geometry>
        <mesh
          filename="package://rocker_description/meshes/rr_wheel.STL" />
      </geometry>
    </collision>
  </link>
  <joint
    name="rr_wheel_joint"
    type="continuous">
    <origin
      xyz="0.000157091141341666 -0.0908967088232534 -0.0809699812101119"
      rpy="-1.5707963267949 0 0" />
    <parent
      link="steer_rr" />
    <child
      link="rr_wheel" />
    <axis
      xyz="0 0 -1" />
    <limit
      lower="-10"
      upper="10"
      effort="10"
      velocity="100" />
  </joint>
    <!-- ===== TRANSMISSIONS FOR ACTUATED JOINTS ===== -->
  
  <!-- Wheel velocity transmissions -->
  <transmission name="fl_wheel_trans">
    <type>transmission_interface/SimpleTransmission</type>
    <joint name="fl_wheel_joint">
      <hardwareInterface>hardware_interface/VelocityJointInterface</hardwareInterface>
    </joint>
    <actuator name="fl_wheel_motor">
      <hardwareInterface>hardware_interface/VelocityJointInterface</hardwareInterface>
      <mechanicalReduction>1</mechanicalReduction>
    </actuator>
  </transmission>

  <transmission name="rl_wheel_trans">
    <type>transmission_interface/SimpleTransmission</type>
    <joint name="rl_wheel_joint">
      <hardwareInterface>hardware_interface/VelocityJointInterface</hardwareInterface>
    </joint>
    <actuator name="rl_wheel_motor">
      <hardwareInterface>hardware_interface/VelocityJointInterface</hardwareInterface>
      <mechanicalReduction>1</mechanicalReduction>
    </actuator>
  </transmission>

  <transmission name="fr_wheel_trans">
    <type>transmission_interface/SimpleTransmission</type>
    <joint name="fr_wheel_joint">
      <hardwareInterface>hardware_interface/VelocityJointInterface</hardwareInterface>
    </joint>
    <actuator name="fr_wheel_motor">
      <hardwareInterface>hardware_interface/VelocityJointInterface</hardwareInterface>
      <mechanicalReduction>1</mechanicalReduction>
    </actuator>
  </transmission>

  <transmission name="rr_wheel_trans">
    <type>transmission_interface/SimpleTransmission</type>
    <joint name="rr_wheel_joint">
      <hardwareInterface>hardware_interface/VelocityJointInterface</hardwareInterface>
    </joint>
    <actuator name="rr_wheel_motor">
      <hardwareInterface>hardware_interface/VelocityJointInterface</hardwareInterface>
      <mechanicalReduction>1</mechanicalReduction>
    </actuator>
  </transmission>

  <!-- Steering position transmissions -->
  <transmission name="steer_fl_trans">
    <type>transmission_interface/SimpleTransmission</type>
    <joint name="steer_fl_joint">
      <hardwareInterface>hardware_interface/PositionJointInterface</hardwareInterface>
    </joint>
    <actuator name="steer_fl_motor">
      <hardwareInterface>hardware_interface/PositionJointInterface</hardwareInterface>
      <mechanicalReduction>1</mechanicalReduction>
    </actuator>
  </transmission>

  <transmission name="steer_rl_trans">
    <type>transmission_interface/SimpleTransmission</type>
    <joint name="steer_rl_joint">
      <hardwareInterface>hardware_interface/PositionJointInterface</hardwareInterface>
    </joint>
    <actuator name="steer_rl_motor">
      <hardwareInterface>hardware_interface/PositionJointInterface</hardwareInterface>
      <mechanicalReduction>1</mechanicalReduction>
    </actuator>
  </transmission>

  <transmission name="steer_fr_trans">
    <type>transmission_interface/SimpleTransmission</type>
    <joint name="steer_fr_joint">
      <hardwareInterface>hardware_interface/PositionJointInterface</hardwareInterface>
    </joint>
    <actuator name="steer_fr_motor">
      <hardwareInterface>hardware_interface/PositionJointInterface</hardwareInterface>
      <mechanicalReduction>1</mechanicalReduction>
    </actuator>
  </transmission>

  <transmission name="steer_rr_trans">
    <type>transmission_interface/SimpleTransmission</type>
    <joint name="steer_rr_joint">
      <hardwareInterface>hardware_interface/PositionJointInterface</hardwareInterface>
    </joint>
    <actuator name="steer_rr_motor">
      <hardwareInterface>hardware_interface/PositionJointInterface</hardwareInterface>
      <mechanicalReduction>1</mechanicalReduction>
    </actuator>
  </transmission>


</robot>