<?xml version="1.0" encoding="utf-8"?>
<!-- This URDF was automatically created by SolidWorks to URDF Exporter! Originally created by Stephen Brawner (brawner@gmail.com) 
     Commit Version: 1.6.0-4-g7f85cfe  Build Version: 1.6.7995.38578
     For more information, please see http://wiki.ros.org/sw_urdf_exporter -->
<robot name="rocker" xmlns:xacro="http://ros.org/wiki/xacro">
  <!-- Start GZ or Ignition depending on ROS 2 Version -->
  <xacro:arg name="is_ignition" default="true"/>

  <!-- Include Gazebo Parameters -->
  <xacro:include filename="$(find rocker_description)/urdf/rocker_gazebo.xacro" />
  <!-- Include control -->
  <xacro:include filename="$(find rocker_description)/urdf/rocker_ros2_control.xacro"/>
  <link
    name="base_link">
    <inertial>
      <origin
        xyz="0.00298859191128537 0.00327281389503588 0.0236277353082409"
        rpy="0 0 0" />
      <mass
        value="3.54225026427668" />
      <inertia
        ixx="0.0133706956982974"
        ixy="-2.17144708939564E-18"
        ixz="-1.2927668928213E-05"
        iyy="0.014433056958566"
        iyz="-1.18489830462864E-19"
        izz="0.0248980091378906" />
    </inertial>
    <visual>
      <origin
        xyz="0 0 0"
        rpy="0 0 0" />
      <geometry>
        <mesh
          filename="package://rocker_description/meshes/base_link.STL" />
      </geometry>
      <material
        name="">
        <color
          rgba="1 0 0 1" />
      </material>
    </visual>
    <collision>
      <origin
        xyz="0 0 0"
        rpy="0 0 0" />
      <geometry>
        <mesh
          filename="package://rocker_description/meshes/base_link.STL" />
      </geometry>
    </collision>
  </link>
  <link
    name="rocker_left">
    <inertial>
      <origin
        xyz="-0.00596279660340987 0.019311656792217 0.00821775120018922"
        rpy="0 0 0" />
      <mass
        value="0.548279466495107" />
      <inertia
        ixx="0.000160712183240721"
        ixy="-1.18295175490068E-05"
        ixz="4.65341036035169E-08"
        iyy="0.00145712336713844"
        iyz="2.38546497105557E-06"
        izz="0.00150112676292675" />
    </inertial>
    <visual>
      <origin
        xyz="0 0 0"
        rpy="0 0 0" />
      <geometry>
        <mesh
          filename="package://rocker_description/meshes/rocker_left.STL" />
      </geometry>
      <material
        name="">
        <color
          rgba="0.752941176470588 0.752941176470588 0.752941176470588 1" />
      </material>
    </visual>
    <collision>
      <origin
        xyz="0 0 0"
        rpy="0 0 0" />
      <geometry>
        <mesh
          filename="package://rocker_description/meshes/rocker_left.STL" />
      </geometry>
    </collision>
  </link>
  <joint
    name="rocker_left_joint"
    type="revolute">
    <origin
      xyz="-0.012023 0.14327 0.0036435"
      rpy="-1.5708 0 0" />
    <parent
      link="base_link" />
    <child
      link="rocker_left" />
    <axis
      xyz="0 0 -1" />
    <limit
      lower="-0.785"
      upper="0.785"
      effort="10"
      velocity="20" />
  </joint>
  <link
    name="steer_fl">
    <inertial>
      <origin
        xyz="0.000519302806489791 0.00116147489574503 -0.072249011838569"
        rpy="0 0 0" />
      <mass
        value="0.0538768873270146" />
      <inertia
        ixx="1.72835692633752E-05"
        ixy="1.86524259779787E-10"
        ixz="1.22947445955916E-09"
        iyy="1.2650499733089E-05"
        iyz="1.03479920307063E-12"
        izz="1.0115174825469E-05" />
    </inertial>
    <visual>
      <origin
        xyz="0 0 0"
        rpy="0 0 0" />
      <geometry>
        <mesh
          filename="package://rocker_description/meshes/steer_fl.STL" />
      </geometry>
      <material
        name="">
        <color
          rgba="0.752941176470588 0.752941176470588 0.752941176470588 1" />
      </material>
    </visual>
    <collision>
      <origin
        xyz="0 0 0"
        rpy="0 0 0" />
      <geometry>
        <mesh
          filename="package://rocker_description/meshes/steer_fl.STL" />
      </geometry>
    </collision>
  </link>
  <joint
    name="steer_fl_joint"
    type="revolute">
    <origin
      xyz="0.10949 0.037941 0.046566"
      rpy="1.5708 0 0" />
    <parent
      link="rocker_left" />
    <child
      link="steer_fl" />
    <axis
      xyz="0 0 -1" />
    <limit
      lower="-3.14"
      upper="3.14"
      effort="10"
      velocity="20" />
  </joint>
  <link
    name="fl_wheel">
    <inertial>
      <origin
        xyz="0.00209895984803671 -0.00193945272577944 -0.0284087458310821"
        rpy="0 0 0" />
      <mass
        value="0.13017290647518" />
      <inertia
        ixx="0.000124778074397082"
        ixy="-7.56745189271209E-12"
        ixz="-1.0927757268831E-11"
        iyy="0.000124777976595369"
        iyz="-2.36402552812522E-12"
        izz="0.000234671292019043" />
    </inertial>
    <visual>
      <origin
        xyz="0 0 0"
        rpy="0 0 0" />
      <geometry>
        <mesh
          filename="package://rocker_description/meshes/fl_wheel.STL" />
      </geometry>
      <material
        name="">
        <color
          rgba="0.792156862745098 0.819607843137255 0.933333333333333 1" />
      </material>
    </visual>
    <collision>
      <origin
        xyz="0 0 0"
        rpy="0 0 0" />
      <geometry>
        <mesh
          filename="package://rocker_description/meshes/fl_wheel.STL" />
      </geometry>
    </collision>
  </link>
  <joint
    name="fl_wheel_joint"
    type="continuous">
    <origin
      xyz="-0.0015781 0.090897 -0.080955"
      rpy="-1.5708 0 0" />
    <parent
      link="steer_fl" />
    <child
      link="fl_wheel" />
    <axis
      xyz="0 0 -1" />
    <limit
      lower="-10"
      upper="10"
      effort="10"
      velocity="100" />
  </joint>
  <link
    name="steer_rl">
    <inertial>
      <origin
        xyz="0.000484941569044394 0.00116147486494461 -0.0761644406147317"
        rpy="0 0 0" />
      <mass
        value="0.053876887039627" />
      <inertia
        ixx="1.72835692580122E-05"
        ixy="1.86520191057722E-10"
        ixz="1.22945286982952E-09"
        iyy="1.26504997081888E-05"
        iyz="1.03201975349867E-12"
        izz="1.01151748056035E-05" />
    </inertial>
    <visual>
      <origin
        xyz="0 0 0"
        rpy="0 0 0" />
      <geometry>
        <mesh
          filename="package://rocker_description/meshes/steer_rl.STL" />
      </geometry>
      <material
        name="">
        <color
          rgba="0.752941176470588 0.752941176470588 0.752941176470588 1" />
      </material>
    </visual>
    <collision>
      <origin
        xyz="0 0 0"
        rpy="0 0 0" />
      <geometry>
        <mesh
          filename="package://rocker_description/meshes/steer_rl.STL" />
      </geometry>
    </collision>
  </link>
  <joint
    name="steer_rl_joint"
    type="revolute">
    <origin
      xyz="-0.11047 0.034053 0.046566"
      rpy="1.5708 0 0" />
    <parent
      link="rocker_left" />
    <child
      link="steer_rl" />
    <axis
      xyz="0 0 -1" />
    <limit
      lower="-0.785"
      upper="0.785"
      effort="10"
      velocity="20" />
  </joint>
  <link
    name="rl_wheel">
    <inertial>
      <origin
        xyz="0.00206456857074838 0.00197597049736126 -0.0284087458310854"
        rpy="0 0 0" />
      <mass
        value="0.130172906475179" />
      <inertia
        ixx="0.000124777994283405"
        ixy="3.83968738303507E-11"
        ixz="1.71836065112964E-12"
        iyy="0.000124778056709046"
        iyz="1.10477040342025E-11"
        izz="0.000234671292019043" />
    </inertial>
    <visual>
      <origin
        xyz="0 0 0"
        rpy="0 0 0" />
      <geometry>
        <mesh
          filename="package://rocker_description/meshes/rl_wheel.STL" />
      </geometry>
      <material
        name="">
        <color
          rgba="0.792156862745098 0.819607843137255 0.933333333333333 1" />
      </material>
    </visual>
    <collision>
      <origin
        xyz="0 0 0"
        rpy="0 0 0" />
      <geometry>
        <mesh
          filename="package://rocker_description/meshes/rl_wheel.STL" />
      </geometry>
    </collision>
  </link>
  <joint
    name="rl_wheel_joint"
    type="continuous">
    <origin
      xyz="-0.0015781 0.090897 -0.080955"
      rpy="-1.5708 0 0" />
    <parent
      link="steer_rl" />
    <child
      link="rl_wheel" />
    <axis
      xyz="0 0 -1" />
    <limit
      lower="-10"
      upper="10"
      effort="10"
      velocity="100" />
  </joint>
  <link
    name="rocker_right">
    <inertial>
      <origin
        xyz="-0.00596288573860194 -0.0193116567449316 0.00817977272543077"
        rpy="0 0 0" />
      <mass
        value="0.548279467986759" />
      <inertia
        ixx="0.000160712214916101"
        ixy="1.170043772776E-05"
        ixz="-4.59530273941062E-08"
        iyy="0.00145712333528538"
        iyz="-2.31782015149321E-06"
        izz="0.00150112676270733" />
    </inertial>
    <visual>
      <origin
        xyz="0 0 0"
        rpy="0 0 0" />
      <geometry>
        <mesh
          filename="package://rocker_description/meshes/rocker_right.STL" />
      </geometry>
      <material
        name="">
        <color
          rgba="0.752941176470588 0.752941176470588 0.752941176470588 1" />
      </material>
    </visual>
    <collision>
      <origin
        xyz="0 0 0"
        rpy="0 0 0" />
      <geometry>
        <mesh
          filename="package://rocker_description/meshes/rocker_right.STL" />
      </geometry>
    </collision>
  </link>
  <joint
    name="rocker_right_joint"
    type="revolute">
    <origin
      xyz="-0.012023 -0.13673 0.0036435"
      rpy="1.5708 0 0" />
    <parent
      link="base_link" />
    <child
      link="rocker_right" />
    <axis
      xyz="0 0 -1" />
    <limit
      lower="-0.785"
      upper="0.785"
      effort="10"
      velocity="100" />
  </joint>
  <link
    name="steer_fr">
    <inertial>
      <origin
        xyz="0.000814806413008712 -0.00116147492243543 -0.0722542108674373"
        rpy="0 0 0" />
      <mass
        value="0.0538768878184284" />
      <inertia
        ixx="1.72835694548748E-05"
        ixy="1.86529294081939E-10"
        ixz="5.41767155045705E-10"
        iyy="1.26504997493636E-05"
        iyz="-9.96207531427938E-13"
        izz="1.01151746557608E-05" />
    </inertial>
    <visual>
      <origin
        xyz="0 0 0"
        rpy="0 0 0" />
      <geometry>
        <mesh
          filename="package://rocker_description/meshes/steer_fr.STL" />
      </geometry>
      <material
        name="">
        <color
          rgba="0.752941176470588 0.752941176470588 0.752941176470588 1" />
      </material>
    </visual>
    <collision>
      <origin
        xyz="0 0 0"
        rpy="0 0 0" />
      <geometry>
        <mesh
          filename="package://rocker_description/meshes/steer_fr.STL" />
      </geometry>
    </collision>
  </link>
  <joint
    name="steer_fr_joint"
    type="revolute">
    <origin
      xyz="0.1092 -0.037936 0.046481"
      rpy="-1.5708 0 0" />
    <parent
      link="rocker_right" />
    <child
      link="steer_fr" />
    <axis
      xyz="0 0 -1" />
    <limit
      lower="-3.14"
      upper="3.14"
      effort="10"
      velocity="20" />
  </joint>
  <link
    name="fr_wheel">
    <inertial>
      <origin
        xyz="0.00209895681369876 -0.00193945745264902 0.0284087458310822"
        rpy="0 0 0" />
      <mass
        value="0.130172906475179" />
      <inertia
        ixx="0.00012477799927836"
        ixy="-4.1966458835124E-11"
        ixz="2.40039553033582E-12"
        iyy="0.00012477805171409"
        iyz="-1.09198274269616E-11"
        izz="0.000234671292019043" />
    </inertial>
    <visual>
      <origin
        xyz="0 0 0"
        rpy="0 0 0" />
      <geometry>
        <mesh
          filename="package://rocker_description/meshes/fr_wheel.STL" />
      </geometry>
      <material
        name="">
        <color
          rgba="0.792156862745098 0.819607843137255 0.933333333333333 1" />
      </material>
    </visual>
    <collision>
      <origin
        xyz="0 0 0"
        rpy="0 0 0" />
      <geometry>
        <mesh
          filename="package://rocker_description/meshes/fr_wheel.STL" />
      </geometry>
    </collision>
  </link>
  <joint
    name="fr_wheel_joint"
    type="revolute">
    <origin
      xyz="-0.001284 -0.090897 -0.08096"
      rpy="-1.5708 0 0" />
    <parent
      link="steer_fr" />
    <child
      link="fr_wheel" />
    <axis
      xyz="0 0 -1" />
    <limit
      lower="-10"
      upper="10"
      effort="10"
      velocity="100" />
  </joint>
  <link
    name="steer_rr">
    <inertial>
      <origin
        xyz="0.00078044532898389 -0.00116147486024443 -0.0761696395699586"
        rpy="0 0 0" />
      <mass
        value="0.0538768870506308" />
      <inertia
        ixx="1.72835694385811E-05"
        ixy="1.86520500931445E-10"
        ixz="5.41764435174726E-10"
        iyy="1.26504997110791E-05"
        iyz="-9.9760073830718E-13"
        izz="1.01151746289469E-05" />
    </inertial>
    <visual>
      <origin
        xyz="0 0 0"
        rpy="0 0 0" />
      <geometry>
        <mesh
          filename="package://rocker_description/meshes/steer_rr.STL" />
      </geometry>
      <material
        name="">
        <color
          rgba="0.752941176470588 0.752941176470588 0.752941176470588 1" />
      </material>
    </visual>
    <collision>
      <origin
        xyz="0 0 0"
        rpy="0 0 0" />
      <geometry>
        <mesh
          filename="package://rocker_description/meshes/steer_rr.STL" />
      </geometry>
    </collision>
  </link>
  <joint
    name="steer_rr_joint"
    type="revolute">
    <origin
      xyz="-0.11077 -0.034048 0.046481"
      rpy="-1.5708 0 0" />
    <parent
      link="rocker_right" />
    <child
      link="steer_rr" />
    <axis
      xyz="0 0 -1" />
    <limit
      lower="-3.14"
      upper="3.14"
      effort="10"
      velocity="20" />
  </joint>
  <link
    name="rr_wheel">
    <inertial>
      <origin
        xyz="0.00206459264032307 0.00197596861393125 0.0284087458310822"
        rpy="0 0 0" />
      <mass
        value="0.13017290647518" />
      <inertia
        ixx="0.00012477798399415"
        ixy="-2.69469455067178E-11"
        ixz="-2.09870342277697E-14"
        iyy="0.0001247780669983"
        iyz="-1.11805213846279E-11"
        izz="0.000234671292019043" />
    </inertial>
    <visual>
      <origin
        xyz="0 0 0"
        rpy="0 0 0" />
      <geometry>
        <mesh
          filename="package://rocker_description/meshes/rr_wheel.STL" />
      </geometry>
      <material
        name="">
        <color
          rgba="0.792156862745098 0.819607843137255 0.933333333333333 1" />
      </material>
    </visual>
    <collision>
      <origin
        xyz="0 0 0"
        rpy="0 0 0" />
      <geometry>
        <mesh
          filename="package://rocker_description/meshes/rr_wheel.STL" />
      </geometry>
    </collision>
  </link>
  <joint
    name="rr_wheel_joint"
    type="continuous">
    <origin
      xyz="-0.001284 -0.090897 -0.08096"
      rpy="-1.5708 0 0" />
    <parent
      link="steer_rr" />
    <child
      link="rr_wheel" />
    <axis
      xyz="0 0 -1" />
    <limit
      lower="-10"
      upper="10"
      effort="10"
      velocity="100" />
  </joint>
  <link
    name="diff_link">
    <inertial>
      <origin
        xyz="0.0236047033494912 3.38606037500466E-07 0.00680399175128779"
        rpy="0 0 0" />
      <mass
        value="0.218473302594945" />
      <inertia
        ixx="0.000709218973632844"
        ixy="-4.54890286688117E-11"
        ixz="-5.80923681517665E-07"
        iyy="2.67923062738046E-05"
        iyz="-9.2820020049121E-10"
        izz="0.000717476916902687" />
    </inertial>
    <visual>
      <origin
        xyz="0 0 0"
        rpy="0 0 0" />
      <geometry>
        <mesh
          filename="package://rocker_description/meshes/diff_link.STL" />
      </geometry>
      <material
        name="">
        <color
          rgba="0.752941176470588 0.752941176470588 0.752941176470588 1" />
      </material>
    </visual>
    <collision>
      <origin
        xyz="0 0 0"
        rpy="0 0 0" />
      <geometry>
        <mesh
          filename="package://rocker_description/meshes/diff_link.STL" />
      </geometry>
    </collision>
  </link>
  <joint
    name="diff_link_joint"
    type="revolute">
    <origin
      xyz="0.062977 0.0032728 0.063644"
      rpy="0 0 0" />
    <parent
      link="base_link" />
    <child
      link="diff_link" />
    <axis
      xyz="0 0 -1" />
    <limit
      lower="-0.785"
      upper="0.785"
      effort="10"
      velocity="20" />
  </joint>
      <!-- ===== TRANSMISSIONS FOR ACTUATED JOINTS ===== -->
  
  <!-- Wheel velocity transmissions -->
  <transmission name="fl_wheel_trans">
    <type>transmission_interface/SimpleTransmission</type>
    <joint name="fl_wheel_joint">
      <hardwareInterface>hardware_interface/VelocityJointInterface</hardwareInterface>
    </joint>
    <actuator name="fl_wheel_motor">
      <hardwareInterface>hardware_interface/VelocityJointInterface</hardwareInterface>
      <mechanicalReduction>1</mechanicalReduction>
    </actuator>
  </transmission>

  <transmission name="rl_wheel_trans">
    <type>transmission_interface/SimpleTransmission</type>
    <joint name="rl_wheel_joint">
      <hardwareInterface>hardware_interface/VelocityJointInterface</hardwareInterface>
    </joint>
    <actuator name="rl_wheel_motor">
      <hardwareInterface>hardware_interface/VelocityJointInterface</hardwareInterface>
      <mechanicalReduction>1</mechanicalReduction>
    </actuator>
  </transmission>

  <transmission name="fr_wheel_trans">
    <type>transmission_interface/SimpleTransmission</type>
    <joint name="fr_wheel_joint">
      <hardwareInterface>hardware_interface/VelocityJointInterface</hardwareInterface>
    </joint>
    <actuator name="fr_wheel_motor">
      <hardwareInterface>hardware_interface/VelocityJointInterface</hardwareInterface>
      <mechanicalReduction>1</mechanicalReduction>
    </actuator>
  </transmission>

  <transmission name="rr_wheel_trans">
    <type>transmission_interface/SimpleTransmission</type>
    <joint name="rr_wheel_joint">
      <hardwareInterface>hardware_interface/VelocityJointInterface</hardwareInterface>
    </joint>
    <actuator name="rr_wheel_motor">
      <hardwareInterface>hardware_interface/VelocityJointInterface</hardwareInterface>
      <mechanicalReduction>1</mechanicalReduction>
    </actuator>
  </transmission>

  <!-- Steering position transmissions -->
  <transmission name="steer_fl_trans">
    <type>transmission_interface/SimpleTransmission</type>
    <joint name="steer_fl_joint">
      <hardwareInterface>hardware_interface/PositionJointInterface</hardwareInterface>
    </joint>
    <actuator name="steer_fl_motor">
      <hardwareInterface>hardware_interface/PositionJointInterface</hardwareInterface>
      <mechanicalReduction>1</mechanicalReduction>
    </actuator>
  </transmission>

  <transmission name="steer_rl_trans">
    <type>transmission_interface/SimpleTransmission</type>
    <joint name="steer_rl_joint">
      <hardwareInterface>hardware_interface/PositionJointInterface</hardwareInterface>
    </joint>
    <actuator name="steer_rl_motor">
      <hardwareInterface>hardware_interface/PositionJointInterface</hardwareInterface>
      <mechanicalReduction>1</mechanicalReduction>
    </actuator>
  </transmission>

  <transmission name="steer_fr_trans">
    <type>transmission_interface/SimpleTransmission</type>
    <joint name="steer_fr_joint">
      <hardwareInterface>hardware_interface/PositionJointInterface</hardwareInterface>
    </joint>
    <actuator name="steer_fr_motor">
      <hardwareInterface>hardware_interface/PositionJointInterface</hardwareInterface>
      <mechanicalReduction>1</mechanicalReduction>
    </actuator>
  </transmission>

  <transmission name="steer_rr_trans">
    <type>transmission_interface/SimpleTransmission</type>
    <joint name="steer_rr_joint">
      <hardwareInterface>hardware_interface/PositionJointInterface</hardwareInterface>
    </joint>
    <actuator name="steer_rr_motor">
      <hardwareInterface>hardware_interface/PositionJointInterface</hardwareInterface>
      <mechanicalReduction>1</mechanicalReduction>
    </actuator>
  </transmission>
</robot>